<?xml version="1.0"?>
<robot xmlns:xacro="http://www.ros.org/wiki/xacro">

    <material name="white">
        <color rgba="1 1 1 1" />
    </material>
    <material name="orange">
        <color rgba="1 0.3 0.1 1" />
    </material>
    <material name="blue">
        <color rgba="0.2 0.2 1 1" />
    </material>
    <material name="black">
        <color rgba="0 0 0 1" />
    </material>

<!-- Base link -->

    <link name="base_link">
    </link>

<!-- Chassis link -->

    <joint name="chassis_joint" type="fixed">
        <parent link="base_link"/>
        <child link="chassis"/>
        <origin xyz="0 0 0"/>
    </joint>

    <link name="chassis">
        <visual>
            <origin xyz="0.4 0 0.1"/>
            <geometry> 
                <box size="0.8 0.4 0.2"/>       
            </geometry>
            <material name="white"/>
        </visual>
        <collision>
            <origin xyz="0.4 0 0.1"/>
            <geometry> 
                <box size="0.8 0.4 0.2"/>       
            </geometry>
        </collision>
        <xacro:inertial_box mass="0.5" x="0.8" y="0.4" z="0.2">
            <origin xyz="0.4 0 0.1" rpy="0 0 0"/>
        </xacro:inertial_box>
    </link>

    <!--  Left Front Wheel  -->
    <joint name="left_front_wheel" type="continuous">
        <parent link="base_link"/>
        <child link="left_front_wheel"/>
        <origin xyz="0.7 0.2 0.01" rpy="-${pi/2} 0 0"/>
        <axis xyz="0 0 1"/>
    </joint>
    <link name="left_front_wheel">
        <visual>
            <geometry>
                <cylinder radius="0.065" length="0.025"/>
            </geometry>
            <material name="blue"/>
        </visual>
        <collision>
            <geometry>
                <cylinder radius="0.065" length="0.025"/>
            </geometry>
        </collision>
        <xacro:inertial_cylinder mass="0.1" length="0.025" radius="0.065"/>
            <origin xyz="0 0 0" rpy="0 0 0"/>
        <xacro:inertial_cylinder/>
    </link>

      <!--  Right Front Wheel  -->
    <joint name="right_front_wheel" type="continuous">
        <parent link="base_link"/>
        <child link="right_front_wheel"/>
        <origin xyz="0.7 -0.2 0.01" rpy="${pi/2} 0 0"/>
        <axis xyz="0 0 -1"/>
    </joint>
    <link name="right_front_wheel">
        <visual>
            <geometry>
                <cylinder radius="0.065" length="0.025"/>
            </geometry>
            <material name="blue"/>
        </visual>
        <collision>
            <geometry>
                <cylinder radius="0.065" length="0.025"/>
            </geometry>
        </collision>
        <xacro:inertial_cylinder mass="0.1" length="0.025" radius="0.065"/>
            <origin xyz="0 0 0" rpy="0 0 0"/>
        <xacro:inertial_cylinder/>
    </link>

    <!--  Left Rear Wheel  -->
    <joint name="left_rear_wheel" type="continuous">
        <parent link="base_link"/>
        <child link="left_rear_wheel"/>
        <origin xyz="0.1 0.2 0.01" rpy="-${pi/2} 0 0"/>
        <axis xyz="0 0 1"/>
    </joint>
    <link name="left_rear_wheel">
        <visual>
            <geometry>
                <cylinder radius="0.065" length="0.025"/>
            </geometry>
            <material name="blue"/>
        </visual>
        <collision>
            <geometry>
                <cylinder radius="0.065" length="0.025"/>
            </geometry>
        </collision>
        <xacro:inertial_cylinder mass="0.1" length="0.025" radius="0.065"/>
            <origin xyz="0 0 0" rpy="0 0 0"/>
        <xacro:inertial_cylinder/>
    </link>

      <!--  Right Rear Wheel  -->
    <joint name="right_rear_wheel" type="continuous">
        <parent link="base_link"/>
        <child link="right_rear_wheel"/>
        <origin xyz="0.1 -0.2 0.01" rpy="${pi/2} 0 0"/>
        <axis xyz="0 0 -1"/>
    </joint>
    <link name="right_rear_wheel">
        <visual>
            <geometry>
                <cylinder radius="0.065" length="0.025"/>
            </geometry>
            <material name="blue"/>
        </visual>
        <collision>
            <geometry>
                <cylinder radius="0.065" length="0.025"/>
            </geometry>
        </collision>
        <xacro:inertial_cylinder mass="0.1" length="0.025" radius="0.065"/>
            <origin xyz="0 0 0" rpy="0 0 0"/>
        <xacro:inertial_cylinder/>
    </link>


</robot>